Traceback (most recent call last):
  File "C:\Users\vkoul\Anaconda3\lib\site-packages\jupyter_cache\executors\utils.py", line 51, in single_nb_execution
    executenb(
  File "C:\Users\vkoul\Anaconda3\lib\site-packages\nbclient\client.py", line 1204, in execute
    return NotebookClient(nb=nb, resources=resources, km=km, **kwargs).execute()
  File "C:\Users\vkoul\Anaconda3\lib\site-packages\nbclient\util.py", line 84, in wrapped
    return just_run(coro(*args, **kwargs))
  File "C:\Users\vkoul\Anaconda3\lib\site-packages\nbclient\util.py", line 62, in just_run
    return loop.run_until_complete(coro)
  File "C:\Users\vkoul\Anaconda3\lib\asyncio\base_events.py", line 647, in run_until_complete
    return future.result()
  File "C:\Users\vkoul\Anaconda3\lib\site-packages\nbclient\client.py", line 663, in async_execute
    await self.async_execute_cell(
  File "C:\Users\vkoul\Anaconda3\lib\site-packages\nbclient\client.py", line 965, in async_execute_cell
    await self._check_raise_for_error(cell, cell_index, exec_reply)
  File "C:\Users\vkoul\Anaconda3\lib\site-packages\nbclient\client.py", line 862, in _check_raise_for_error
    raise CellExecutionError.from_cell_and_msg(cell, exec_reply_content)
nbclient.exceptions.CellExecutionError: An error occurred while executing the following cell:
------------------
os.makedirs('new_folder2') # by default it will create it in the working directory
------------------

[1;31m---------------------------------------------------------------------------[0m
[1;31mFileExistsError[0m                           Traceback (most recent call last)
Input [1;32mIn [37][0m, in [0;36m<cell line: 1>[1;34m()[0m
[1;32m----> 1[0m [43mos[49m[38;5;241;43m.[39;49m[43mmakedirs[49m[43m([49m[38;5;124;43m'[39;49m[38;5;124;43mnew_folder2[39;49m[38;5;124;43m'[39;49m[43m)[49m

File [1;32m~\Anaconda3\lib\os.py:225[0m, in [0;36mmakedirs[1;34m(name, mode, exist_ok)[0m
[0;32m    223[0m         [38;5;28;01mreturn[39;00m
[0;32m    224[0m [38;5;28;01mtry[39;00m:
[1;32m--> 225[0m     [43mmkdir[49m[43m([49m[43mname[49m[43m,[49m[43m [49m[43mmode[49m[43m)[49m
[0;32m    226[0m [38;5;28;01mexcept[39;00m [38;5;167;01mOSError[39;00m:
[0;32m    227[0m     [38;5;66;03m# Cannot rely on checking for EEXIST, since the operating system[39;00m
[0;32m    228[0m     [38;5;66;03m# could give priority to other errors like EACCES or EROFS[39;00m
[0;32m    229[0m     [38;5;28;01mif[39;00m [38;5;129;01mnot[39;00m exist_ok [38;5;129;01mor[39;00m [38;5;129;01mnot[39;00m path[38;5;241m.[39misdir(name):

[1;31mFileExistsError[0m: [WinError 183] Cannot create a file when that file already exists: 'new_folder2'
FileExistsError: [WinError 183] Cannot create a file when that file already exists: 'new_folder2'

